Workbook

Sheet DCF Valuation
A2: X | B2: Free Cash Flow Build
B3: ($ in millions) | E3: 2025E | F3: 2026E | G3: 2027E | H3: 2028E | I3: 2029E
B5: EBIT | E5: ='Income Statement Forecast'!F16 -> 11564.171 | F5: ='Income Statement Forecast'!G16 -> 13984.055 | G5: ='Income Statement Forecast'!H16 -> 15814.814 | H5: ='Income Statement Forecast'!I16 -> 16368.332 | I5: ='Income Statement Forecast'!J16 -> 18937.069
B6: Taxes | E6: =-E5*'Forecasted Assumptions'!G37 -> -2744.1777 | F6: =-F5*'Forecasted Assumptions'!H37 -> -3318.4163 | G6: =-G5*'Forecasted Assumptions'!I37 -> -3752.8553 | H6: =-H5*'Forecasted Assumptions'!J37 -> -3884.2052 | I6: =-I5*'Forecasted Assumptions'!K37 -> 0
B7: NOPAT | E7: =SUM(E5:E6) -> 8819.9928 | F7: =SUM(F5:F6) -> 10665.639 | G7: =SUM(G5:G6) -> 12061.958 | H7: =SUM(H5:H6) -> 12484.127 | I7: =SUM(I5:I6) -> 18937.069
B8: D&A | E8: ='Cash Flows Forecast'!G7 -> 5139.7 | F8: ='Cash Flows Forecast'!H7 -> 5345.288 | G8: ='Cash Flows Forecast'!I7 -> 5559.0995 | H8: ='Cash Flows Forecast'!J7 -> 5753.668 | I8: ='Cash Flows Forecast'!K7 -> 5897.5097
B9: NCWC | E9: ='Cash Flows Forecast'!G8 -> -254.55 | F9: ='Cash Flows Forecast'!H8 -> -349.582 | G9: ='Cash Flows Forecast'!I8 -> -363.56528 | H9: ='Cash Flows Forecast'!J8 -> -330.8444 | I9: ='Cash Flows Forecast'!K8 -> -244.58854
B10: Capex | E10: ='Cash Flows Forecast'!G11 -> -5574.36 | F10: ='Cash Flows Forecast'!H11 -> -5797.3344 | G10: ='Cash Flows Forecast'!I11 -> -6029.2278 | H10: ='Cash Flows Forecast'!J11 -> -6240.2507 | I10: ='Cash Flows Forecast'!K11 -> -6396.257
B11: Free Cash Flow to Firm (FCFF) | E11: =SUM(E7:E10) -> 8130.7828 | F11: =SUM(F7:F10) -> 9864.0106 | G11: =SUM(G7:G10) -> 11228.265 | H11: =SUM(H7:H10) -> 11666.7 | I11: =SUM(I7:I10) -> 18193.733
B12: FCFF Growth Rate | E12: N/A | F12: =+F11/E11-1 -> 0.21316863 | G12: =+G11/F11-1 -> 0.13830624 | H12: =+H11/G11-1 -> 0.039047434 | I12: =+I11/H11-1 -> 0.55945842
A14: X | B14: WACC Calculation | F14: DCF Valuation
B15: ($ in millions) | F15: ($ in millions)
B17: Cost of Debt Calculation | F17: Sum of Projected FCFF | I17: =SUM(E11:I11) -> 59083.491
B18: Interest Expense | D18: ='Income Statement Forecast'!F18 -> -594.44745 | F18: Terminal Growth Rate | I18: 0.03
B19: Total Debt | D19: ='Balance Sheet Forecast'!F33 -> 39130 | F19: Years Forecasted | I19: 5
B20: Pre-Tax Cost of Debt | D20: =-D18/D19 -> 0.015191604 | F20: 2030 FCFF | I20: =I11*(1+I18) -> 18739.545
B21: Effective Tax Rate | D21: =('Income Statement Forecast'!E22/'Income Statement Forecast'!E21)*-1 -> 0.23728366 | F21: Terminal Value | I21: =I20/(D35-I18) -> 297777.75
B22: After-Tax Cost of Debt | D22: =+D20*(1-D21) -> 0.011586884 | F22: PV Terminal Value | I22: =I21/(1+D35)^I19 -> 190953.62
F23: Total Enterprise Value | I23: =I22+I17 -> 250037.11
B24: Capital Asset Pricing Model (CAPM) | F24: Net Debt | I24: =('Balance Sheet Forecast'!E33-'Balance Sheet Forecast'!E6) -> 33128
B25: Risk Free Rate (rf) | D25: 0.0444 | F25: Equity Value | I25: =SUM(I23:I24) -> 283165.11
B26: Beta | D26: 1.56 | F26: Shares Outstanding | I26: 1800
B27: Expected Return, Market (rM) | D27: 0.085
B28: Cost of Equity | D28: =D25+D26*(D27-D25) -> 0.107736 | F28: Estimated Share Price | I28: =I25/I26 -> 157.31395
F29: Current Stock Price | I29: 119.54
B30: Debt + Equity Weights | C30: ($) | D30: (%) | F30: Updside/Downside | I30: =(I28/I29)-1 -> 0.31599425
B31: Total Debt Balance | C31: =D19 -> 39130 | D31: =C31/C33 -> 0.15397631
B32: Market Value of Equity | C32: 215000 | D32: =1-D31 -> 0.84602369
B33: Total Capitalization | C33: =SUM(C31:C32) -> 254130 | D33: =SUM(D31:D32) -> 1 | G33: Case Toggle | H33: (1 --> 3): | I33: 1
G34: Active Case: | I34: =CHOOSE(I33, "Base", "Bear", "Bull") -> Base
B35: WACC | D35: =(D22*D31)+(D28*D32) -> 0.092931314
A37: X | B37: Sensitivity Analysis
C39: Estimated Price | D39: Terminal Growth Rate
C40: =I28 -> 157.31395 | D40: 0.02 | E40: =+D40+0.5% -> 0.025 | F40: =+E40+0.5% -> 0.03 | G40: =+F40+0.5% -> 0.035 | H40: =+G40+0.5% -> 0.04
B41: WACC | C41: =C42-0.5% -> 0.0729 | D41: 188.31602 | E41: 203.36792 | F41: 221.92841 | G41: 245.38613 | H41: 275.97386
C42: =C43-0.5% -> 0.0779 | D42: 173.59962 | E42: 185.82244 | F42: 200.59699 | G42: 218.81549 | H42: 241.84098
C43: =+C44-0.5% -> 0.0829 | D43: 161.29559 | E43: 171.38665 | F43: 183.38528 | G43: 197.88884 | H43: 215.77319
C44: =C45-0.5% -> 0.0879 | D44: 150.86886 | E44: 159.31665 | F44: 169.22347 | G44: 181.00303 | H44: 195.24179
C45: =9.29% -> 0.0929 | D45: 141.93123 | E45: 149.08772 | F45: 157.38197 | G45: 167.10874 | H45: 178.67421
C46: =+C45+0.5% -> 0.0979 | D46: 134.19422 | E46: 140.31917 | F46: 147.34619 | G46: 155.49038 | H46: 165.04116
...

Sheet Forecasted Assumptions
A2: Forecasted Assumptions | B2: 2021A | C2: 2022A | D2: 2023A | E2: 2024A | F2: 2025E | G2: 2026E | H2: 2027E | I2: 2028E | J2: 2029E
A4: Income Statement
A6: Revenue Growth Rate
A7: Base (1) | C7: ='Income Statement Forecast'!$C$6/'Income Statement Forecast'!$B$6-1 -> 0.22700169 | D7: ='Income Statement Forecast'!$D$6/'Income Statement Forecast'!$C$6-1 -> 0.074659704 | E7: ='Income Statement Forecast'!$E$6/'Income Statement Forecast'!$D$6-1 -> 0.02770591 | F7: 0.03 | G7: 0.04 | H7: 0.04 | I7: 0.035 | J7: 0.025
A8: Bear (2) | F8: 0.01 | G8: 0.01 | H8: 0.01 | I8: 0.02 | J8: 0.02
A9: Bull (3) | B9: ` | F9: 0.04 | G9: 0.04 | H9: 0.04 | I9: 0.045 | J9: 0.05
A11: COGS/Sales
A12: Base (1) | B12: ='Income Statement Forecast'!$B$7/'Income Statement Forecast'!$B$6 -> 0.66942063 | C12: ='Income Statement Forecast'!$C$7/'Income Statement Forecast'!$C$6 -> 0.65763642 | D12: ='Income Statement Forecast'!$D$7/'Income Statement Forecast'!$D$6 -> 0.66594299 | E12: ='Income Statement Forecast'!$E$7/'Income Statement Forecast'!$E$6 -> 0.64248421 | F12: 0.65 | G12: 0.63 | H12: 0.62 | I12: 0.62 | J12: 0.6
A13: Bear (2) | F13: 0.65 | G13: 0.65 | H13: 0.66 | I13: 0.67 | J13: 0.68
A14: Bull (3) | F14: 0.63 | G14: 0.58 | H14: 0.57 | I14: 0.57 | J14: 0.56
A16: SG&A/Sales
A17: Base (1) | B17: =-'Income Statement Forecast'!$B$11/'Income Statement Forecast'!$B$6 -> 0.20049542 | C17: =-'Income Statement Forecast'!$C$11/'Income Statement Forecast'!$C$6 -> 0.19810933 | D17: =-'Income Statement Forecast'!$D$11/'Income Statement Forecast'!$D$6 -> 0.17251232 | E17: =-'Income Statement Forecast'!$E$11/'Income Statement Forecast'!$E$6 -> 0.17249154 | F17: =E17 -> 0.17249154 | G17: =F17 -> 0.17249154 | H17: 0.17 | I17: =H17 -> 0.17 | J17: =I17 -> 0.17
A18: Bear (2) | F18: 0.18 | G18: 0.18 | H18: 0.19 | I18: 0.19 | J18: 0.19
A19: Bull (3) | F19: 0.17 | G19: 0.165 | H19: 0.16 | I19: 0.155 | J19: 0.15
A21: D%A
A22: Base (1) | B22: =-'Income Statement Forecast'!$B$13/'Income Statement Forecast'!$B$6 -> 0.075810614 | C22: =-'Income Statement Forecast'!$C$13/'Income Statement Forecast'!$C$6 -> 0.062413868 | D22: =-'Income Statement Forecast'!$D$13/'Income Statement Forecast'!$D$6 -> 0.06039506 | E22: =-'Income Statement Forecast'!$E$13/'Income Statement Forecast'!$E$6 -> 0.054618491 | F22: =E22 -> 0.054618491 | G22: =F22 -> 0.054618491 | H22: =G22 -> 0.054618491 | I22: =H22 -> 0.054618491 | J22: =I22 -> 0.054618491
A23: Bear (2) | F23: 0.0546 | G23: 0.05 | H23: 0.05 | I23: 0.045 | J23: 0.045
A24: Bull (3) | F24: 0.0546 | G24: 0.06 | H24: 0.06 | I24: 0.065 | J24: 0.065
A26: Interest Rate Earned on Surplus Cash
A27: Base (1) | B27: - | C27: - | D27: - | E27: - | F27: 0.045 | G27: 0.045 | H27: 0.045 | I27: 0.045 | J27: 0.045
A28: Bear (2) | F28: 0.045 | G28: 0.045 | H28: 0.03 | I28: 0.03 | J28: 0.02
A29: Bull (3) | F29: 0.045 | G29: 0.05 | H29: 0.055 | I29: 0.06 | J29: 0.065
A31: Interest Rate Paid on Additional financing
A32: Base (1) | B32: - | C32: - | D32: - | E32: - | F32: 0.03 | G32: =F32 -> 0.03 | H32: =G32 -> 0.03 | I32: =H32 -> 0.03 | J32: =I32 -> 0.03
A33: Bear (2) | F33: 0.03 | G33: 0.035 | H33: 0.035 | I33: 0.04 | J33: 0.045
A34: Bull (3) | F34: 0.03 | G34: 0.028 | H34: 0.025 | I34: 0.024 | J34: 0.022
A36: Tax Rate
A37: Base (1) | B37: =-'Income Statement Forecast'!$B$22/'Income Statement Forecast'!$B$21 -> 0.0097618118 | C37: =-'Income Statement Forecast'!$C$22/'Income Statement Forecast'!$C$21 -> 0.32771996 | D37: =-'Income Statement Forecast'!$D$22/'Income Statement Forecast'!$D$21 -> 0.28915915 | E37: =-'Income Statement Forecast'!E22/'Income Statement Forecast'!E21 -> 0.23728366 | F37: 0.2373 | G37: 0.2373 | H37: 0.2373 | I37: 0.2373 | J37: 0.2373
A38: Bear (2) | F38: 0.28 | G38: 0.28 | H38: 0.28 | I38: 0.28 | J38: 0.28
A39: Bull (3) | F39: 0.21 | G39: 0.21 | H39: 0.21 | I39: 0.21 | J39: 0.21
A41: Balance Sheet
A43: AR/Sales
A44: Base (1) | B44: ='Balance Sheet Forecast'!$B$7/'Income Statement Forecast'!$B$6 -> 0.19827049 | C44: ='Balance Sheet Forecast'!$C$7/'Income Statement Forecast'!$C$6 -> 0.15294601 | D44: ='Balance Sheet Forecast'!$D$7/'Income Statement Forecast'!$D$6 -> 0.13869828 | E44: ='Balance Sheet Forecast'!$E$7/'Income Statement Forecast'!$E$6 -> 0.13932641 | F44: =E44 -> 0.13932641 | G44: =F44 -> 0.13932641 | H44: =G44 -> 0.13932641 | I44: =H44 -> 0.13932641 | J44: =I44 -> 0.13932641
A45: Bear (2) | F45: 0.14 | G45: 0.15 | H45: 0.15 | I45: 0.16 | J45: 0.17
A46: Bull (3) | F46: 0.14 | G46: 0.13 | H46: 0.13 | I46: 0.12 | J46: 0.12
A48: Inventory/Sales
A49: Base (1) | B49: ='Balance Sheet Forecast'!$B$8/'Income Statement Forecast'!$B$6 -> 0.019742502 | C49: ='Balance Sheet Forecast'!$C$8/'Income Statement Forecast'!$C$6 -> 0.021058485 | D49: ='Balance Sheet Forecast'!$D$8/'Income Statement Forecast'!$D$6 -> 0.022081487 | E49: ='Balance Sheet Forecast'!$E$8/'Income Statement Forecast'!$E$6 -> 0.022131982 | F49: =E49 -> 0.022131982 | G49: =F49 -> 0.022131982 | H49: =G49 -> 0.022131982 | I49: =H49 -> 0.022131982 | J49: =I49 -> 0.022131982
A50: Bear (2) | F50: 0.0221 | G50: 0.024 | H50: 0.024 | I50: 0.025 | J50: 0.026
A51: Bull (3) | F51: 0.0221 | G51: 0.021 | H51: 0.021 | I51: 0.02 | J51: 0.02
A53: Prepaid Expenses
...

Sheet Income Statement Forecast
A1: 3 Statement Model - Income | B1: 2021A | C1: 2022A | D1: 2023A | E1: 2024A | F1: 2025E | G1: 2026E | H1: 2027E | I1: 2028E | J1: 2029E
A3: Income Statement
A4: ($ in millions)
A6: Revenues | B6: {=INDEX('Income Statement'!$B$2:$E$2,6-COLUMN())} -> 67418 | C6: {=INDEX('Income Statement'!$B$2:$E$2,6-COLUMN())} -> 82722 | D6: {=INDEX('Income Statement'!$B$2:$E$2,6-COLUMN())} -> 88898 | E6: {=INDEX('Income Statement'!$B$2:$E$2,6-COLUMN())} -> 91361 | F6: =E6*(1+CHOOSE('DCF Valuation'!$I$33,'Forecasted Assumptions'!F7,'Forecasted Assumptions'!F8,'Forecasted Assumptions'!F9)) -> 94101.83 | G6: =F6*(1+CHOOSE('DCF Valuation'!$I$33,'Forecasted Assumptions'!G7,'Forecasted Assumptions'!G8,'Forecasted Assumptions'!G9)) -> 97865.903 | H6: =G6*(1+CHOOSE('DCF Valuation'!$I$33,'Forecasted Assumptions'!H7,'Forecasted Assumptions'!H8,'Forecasted Assumptions'!H9)) -> 101780.54 | I6: =H6*(1+CHOOSE('DCF Valuation'!$I$33,'Forecasted Assumptions'!I7,'Forecasted Assumptions'!I8,'Forecasted Assumptions'!I9)) -> 105342.86 | J6: =I6*(1+CHOOSE('DCF Valuation'!$I$33,'Forecasted Assumptions'!J7,'Forecasted Assumptions'!J8,'Forecasted Assumptions'!J9)) -> 107976.43
A7: Cost of Goods Sold | B7: {=INDEX('Income Statement'!$B$6:$E$6,6-COLUMN())} -> 45131 | C7: {=INDEX('Income Statement'!$B$6:$E$6,6-COLUMN())} -> 54401 | D7: {=INDEX('Income Statement'!$B$6:$E$6,6-COLUMN())} -> 59201 | E7: {=INDEX('Income Statement'!$B$6:$E$6,6-COLUMN())} -> 58698 | F7: =F6*CHOOSE('DCF Valuation'!$I$33, 'Forecasted Assumptions'!F12, 'Forecasted Assumptions'!F13, 'Forecasted Assumptions'!F14) -> 61166.19 | G7: =G6*CHOOSE('DCF Valuation'!$I$33, 'Forecasted Assumptions'!G12, 'Forecasted Assumptions'!G13, 'Forecasted Assumptions'!G14) -> 61655.519 | H7: =H6*CHOOSE('DCF Valuation'!$I$33, 'Forecasted Assumptions'!H12, 'Forecasted Assumptions'!H13, 'Forecasted Assumptions'!H14) -> 63103.934 | I7: =I6*CHOOSE('DCF Valuation'!$I$33, 'Forecasted Assumptions'!I12, 'Forecasted Assumptions'!I13, 'Forecasted Assumptions'!I14) -> 65312.572 | J7: =J6*CHOOSE('DCF Valuation'!$I$33, 'Forecasted Assumptions'!J12, 'Forecasted Assumptions'!J13, 'Forecasted Assumptions'!J14) -> 64785.858
A8: Gross Profit | B8: =B6-B7 -> 22287 | C8: =C6-C7 -> 28321 | D8: =D6-D7 -> 29697 | E8: =E6-E7 -> 32663 | F8: =F6-F7 -> 32935.641 | G8: =G6-G7 -> 36210.384 | H8: =H6-H7 -> 38676.605 | I8: =I6-I7 -> 40030.286 | J8: =J6-J7 -> 43190.572
A10: Operating Expenses
A11: Selling General & Admin | B11: {=-INDEX('Income Statement'!$B$9:$E$9,6-COLUMN())} -> -13517 | C11: {=-INDEX('Income Statement'!$B$9:$E$9,6-COLUMN())} -> -16388 | D11: {=-INDEX('Income Statement'!$B$9:$E$9,6-COLUMN())} -> -15336 | E11: {=-INDEX('Income Statement'!$B$9:$E$9,6-COLUMN())} -> -15759 | F11: =-F6*CHOOSE('DCF Valuation'!$I$33, 'Forecasted Assumptions'!F17, 'Forecasted Assumptions'!F18, 'Forecasted Assumptions'!F19) -> -16231.77 | G11: =-G6*CHOOSE('DCF Valuation'!$I$33, 'Forecasted Assumptions'!G17, 'Forecasted Assumptions'!G18, 'Forecasted Assumptions'!G19) -> -16881.041 | H11: =-H6*CHOOSE('DCF Valuation'!$I$33, 'Forecasted Assumptions'!H17, 'Forecasted Assumptions'!H18, 'Forecasted Assumptions'!H19) -> -17302.692 | I11: =-I6*CHOOSE('DCF Valuation'!$I$33, 'Forecasted Assumptions'!I17, 'Forecasted Assumptions'!I18, 'Forecasted Assumptions'!I19) -> -17908.286 | J11: =-J6*CHOOSE('DCF Valuation'!$I$33, 'Forecasted Assumptions'!J17, 'Forecasted Assumptions'!J18, 'Forecasted Assumptions'!J19) -> -18355.993
A12: Research & Development | B12: {=INDEX('Income Statement'!$B$11:$E$11,6-COLUMN())} -> -- | C12: {=INDEX('Income Statement'!$B$11:$E$11,6-COLUMN())} -> -- | D12: {=INDEX('Income Statement'!$B$11:$E$11,6-COLUMN())} -> -- | E12: {=INDEX('Income Statement'!$B$11:$E$11,6-COLUMN())} -> -- | F12: =0 -> 0 | G12: =0 -> 0 | H12: =0 -> 0 | I12: =0 -> 0 | J12: =0 -> 0
A13: Depreciation & Amortization | B13: {=-INDEX('Income Statement'!$B$12:$E$12,6-COLUMN())} -> -5111 | C13: {=-INDEX('Income Statement'!$B$12:$E$12,6-COLUMN())} -> -5163 | D13: {=-INDEX('Income Statement'!$B$12:$E$12,6-COLUMN())} -> -5369 | E13: {=-INDEX('Income Statement'!$B$12:$E$12,6-COLUMN())} -> -4990 | F13: =-F6*CHOOSE('DCF Valuation'!$I$33, 'Forecasted Assumptions'!F22, 'Forecasted Assumptions'!F23, 'Forecasted Assumptions'!F24) -> -5139.7 | G13: =-G6*CHOOSE('DCF Valuation'!$I$33, 'Forecasted Assumptions'!G22, 'Forecasted Assumptions'!G23, 'Forecasted Assumptions'!G24) -> -5345.288 | H13: =-H6*CHOOSE('DCF Valuation'!$I$33, 'Forecasted Assumptions'!H22, 'Forecasted Assumptions'!H23, 'Forecasted Assumptions'!H24) -> -5559.0995 | I13: =-I6*CHOOSE('DCF Valuation'!$I$33, 'Forecasted Assumptions'!I22, 'Forecasted Assumptions'!I23, 'Forecasted Assumptions'!I24) -> -5753.668 | J13: =-J6*CHOOSE('DCF Valuation'!$I$33, 'Forecasted Assumptions'!J22, 'Forecasted Assumptions'!J23, 'Forecasted Assumptions'!J24) -> -5897.5097
A14: Unusual Expense (Income) | B14: {=-INDEX('Income Statement'!$B$17:$E$17,6-COLUMN())} -> -528 | C14: {=-INDEX('Income Statement'!$B$17:$E$17,6-COLUMN())} -> -237 | D14: {=-INDEX('Income Statement'!$B$17:$E$17,6-COLUMN())} -> -3892 | E14: {=-INDEX('Income Statement'!$B$17:$E$17,6-COLUMN())} -> -3660 | F14: 0 | G14: 0 | H14: 0 | I14: 0 | J14: 0
A15: Other Operating Expenses | B15: -- | C15: {=-INDEX('Income Statement'!$B$18:$E$18,6-COLUMN())} -> -4 | D15: {=-INDEX('Income Statement'!$B$18:$E$18,6-COLUMN())} -> -73 | E15: -- | F15: =0 -> 0 | G15: =0 -> 0 | H15: =0 -> 0 | I15: =0 -> 0 | J15: =0 -> 0
A16: EBIT | B16: =B8+SUM(B11:B15) -> 3131 | C16: =C8+SUM(C11:C15) -> 6529 | D16: =D8+SUM(D11:D15) -> 5027 | E16: =E8+SUM(E11:E15) -> 8254 | F16: =F8+SUM(F11:F15) -> 11564.171 | G16: =G8+SUM(G11:G15) -> 13984.055 | H16: =H8+SUM(H11:H15) -> 15814.814 | I16: =I8+SUM(I11:I15) -> 16368.332 | J16: =J8+SUM(J11:J15) -> 18937.069
A18: Interest Expense | B18: {=INDEX('Income Statement'!$B$21:$E$21,6-COLUMN())} -> -1546 | C18: {=INDEX('Income Statement'!$B$21:$E$21,6-COLUMN())} -> -1549 | D18: {=INDEX('Income Statement'!$B$21:$E$21,6-COLUMN())} -> -1973 | E18: {=INDEX('Income Statement'!$B$21:$E$21,6-COLUMN())} -> -2070 | F18: =-(('Balance Sheet Forecast'!E33+'Balance Sheet Forecast'!F31)/2)*CHOOSE('DCF Valuation'!$I$33, 'Forecasted Assumptions'!F32, 'Forecasted Assumptions'!F33, 'Forecasted Assumptions'!F34) -> -594.44745 | G18: =-(('Balance Sheet Forecast'!F33+'Balance Sheet Forecast'!G31)/2)*CHOOSE('DCF Valuation'!$I$33, 'Forecasted Assumptions'!G32, 'Forecasted Assumptions'!G33, 'Forecasted Assumptions'!G34) -> -604.74395 | H18: =-(('Balance Sheet Forecast'!G33+'Balance Sheet Forecast'!H31)/2)*CHOOSE('DCF Valuation'!$I$33, 'Forecasted Assumptions'!H32, 'Forecasted Assumptions'!H33, 'Forecasted Assumptions'!H34) -> -615.45231 | I18: =-(('Balance Sheet Forecast'!H33+'Balance Sheet Forecast'!I31)/2)*CHOOSE('DCF Valuation'!$I$33, 'Forecasted Assumptions'!I32, 'Forecasted Assumptions'!I33, 'Forecasted Assumptions'!I34) -> -625.19691 | J18: =-(('Balance Sheet Forecast'!I33+'Balance Sheet Forecast'!J31)/2)*CHOOSE('DCF Valuation'!$I$33, 'Forecasted Assumptions'!J32, 'Forecasted Assumptions'!J33, 'Forecasted Assumptions'!J34) -> -632.40096
A19: Interest And Investment Income | B19: {=INDEX('Income Statement'!$B$23:$E$23,6-COLUMN())} -> 976 | C19: {=INDEX('Income Statement'!$B$23:$E$23,6-COLUMN())} -> 243 | D19: {=INDEX('Income Statement'!$B$23:$E$23,6-COLUMN())} -> 1375 | E19: {=INDEX('Income Statement'!$B$23:$E$23,6-COLUMN())} -> 981 | F19: =(('Balance Sheet Forecast'!E6+'Balance Sheet Forecast'!F6)/2)*CHOOSE('DCF Valuation'!$I$33, 'Forecasted Assumptions'!F27, 'Forecasted Assumptions'!F28, 'Forecasted Assumptions'!F29) -> 270.09 | G19: =(('Balance Sheet Forecast'!F6+'Balance Sheet Forecast'!G6)/2)*CHOOSE('DCF Valuation'!$I$33, 'Forecasted Assumptions'!G27, 'Forecasted Assumptions'!G28, 'Forecasted Assumptions'!G29) -> 270.09 | H19: =(('Balance Sheet Forecast'!G6+'Balance Sheet Forecast'!H6)/2)*CHOOSE('DCF Valuation'!$I$33, 'Forecasted Assumptions'!H27, 'Forecasted Assumptions'!H28, 'Forecasted Assumptions'!H29) -> 270.09 | I19: =(('Balance Sheet Forecast'!H6+'Balance Sheet Forecast'!I6)/2)*CHOOSE('DCF Valuation'!$I$33, 'Forecasted Assumptions'!I27, 'Forecasted Assumptions'!I28, 'Forecasted Assumptions'!I29) -> 270.09 | J19: =(('Balance Sheet Forecast'!I6+'Balance Sheet Forecast'!J6)/2)*CHOOSE('DCF Valuation'!$I$33, 'Forecasted Assumptions'!J27, 'Forecasted Assumptions'!J28, 'Forecasted Assumptions'!J29) -> 270.09
A20: Other Non Operating Income | B20: {=INDEX('Income Statement'!$B$29:$E$29,6-COLUMN())} -> -- | C20: {=INDEX('Income Statement'!$B$29:$E$29,6-COLUMN())} -> 62 | D20: {=INDEX('Income Statement'!$B$29:$E$29,6-COLUMN())} -> 340 | E20: {=INDEX('Income Statement'!$B$29:$E$29,6-COLUMN())} -> 404 | F20: 0 | G20: 0 | H20: 0 | I20: 0 | J20: 0
A21: EBT | B21: =B16+(SUM(B18:B20)) -> 2561 | C21: =C16+(SUM(C18:C20)) -> 5285 | D21: =D16+(SUM(D18:D20)) -> 4769 | E21: =E16+(SUM(E18:E20)) -> 7569 | F21: =F16+(SUM(F18:F20)) -> 11239.813 | G21: =G16+(SUM(G18:G20)) -> 13649.401 | H21: =H16+(SUM(H18:H20)) -> 15469.451 | I21: =I16+(SUM(I18:I20)) -> 16013.225 | J21: =J16+(SUM(J18:J20)) -> 18574.758
A22: Income Tax Expense | B22: {=-INDEX('Income Statement'!$B$31:$E$31,6-COLUMN())} -> -25 | C22: {=-INDEX('Income Statement'!$B$31:$E$31,6-COLUMN())} -> -1732 | D22: {=-INDEX('Income Statement'!$B$31:$E$31,6-COLUMN())} -> -1379 | E22: {=-INDEX('Income Statement'!$B$31:$E$31,6-COLUMN())} -> -1796 | F22: =-F21*CHOOSE('DCF Valuation'!$I$33, 'Forecasted Assumptions'!F37, 'Forecasted Assumptions'!F38, 'Forecasted Assumptions'!F39) -> -2667.2076 | G22: =-G21*CHOOSE('DCF Valuation'!$I$33, 'Forecasted Assumptions'!G37, 'Forecasted Assumptions'!G38, 'Forecasted Assumptions'!G39) -> -3239.003 | H22: =-H21*CHOOSE('DCF Valuation'!$I$33, 'Forecasted Assumptions'!H37, 'Forecasted Assumptions'!H38, 'Forecasted Assumptions'!H39) -> -3670.9008 | I22: =-I21*CHOOSE('DCF Valuation'!$I$33, 'Forecasted Assumptions'!I37, 'Forecasted Assumptions'!I38, 'Forecasted Assumptions'!I39) -> -3799.9384 | J22: =-J21*CHOOSE('DCF Valuation'!$I$33, 'Forecasted Assumptions'!J37, 'Forecasted Assumptions'!J38, 'Forecasted Assumptions'!J39) -> -4407.7901
A23: Net Income | B23: =SUM(B21:B22) -> 2536 | C23: =SUM(C21:C22) -> 3553 | D23: =SUM(D21:D22) -> 3390 | E23: =SUM(E21:E22) -> 5773 | F23: =SUM(F21:F22) -> 8572.6054 | G23: =SUM(G21:G22) -> 10410.398 | H23: =SUM(H21:H22) -> 11798.551 | I23: =SUM(I21:I22) -> 12213.287 | J23: =SUM(J21:J22) -> 14166.968

Sheet Balance Sheet Forecast
A1: 3 Statement Model - Balance | B1: 2021A | C1: 2022A | D1: 2023A | E1: 2024A | F1: 2025E | G1: 2026E | H1: 2027E | I1: 2028E | J1: 2029E
A3: Balance Sheet
A4: ($ in millions)
A6: Total Cash & ST Investments | B6: {=INDEX('Balance Sheet'!$B$4:$E$4,6-COLUMN())} -> 15959 | C6: {=INDEX('Balance Sheet'!$B$4:$E$4,6-COLUMN())} -> 11615 | D6: {=INDEX('Balance Sheet'!$B$4:$E$4,6-COLUMN())} -> 14182 | E6: {=INDEX('Balance Sheet'!$B$4:$E$4,6-COLUMN())} -> 6002 | F6: =E6 -> 6002 | G6: =F6 -> 6002 | H6: =G6 -> 6002 | I6: =H6 -> 6002 | J6: =I6 -> 6002
A7: Total Receivables | B7: {=INDEX('Balance Sheet'!$B$10:$E$10,6-COLUMN())} -> 13367 | C7: {=INDEX('Balance Sheet'!$B$10:$E$10,6-COLUMN())} -> 12652 | D7: {=INDEX('Balance Sheet'!$B$10:$E$10,6-COLUMN())} -> 12330 | E7: {=INDEX('Balance Sheet'!$B$10:$E$10,6-COLUMN())} -> 12729 | F7: ='Income Statement Forecast'!F6*CHOOSE('DCF Valuation'!$I$33, 'Forecasted Assumptions'!F44, 'Forecasted Assumptions'!F45, 'Forecasted Assumptions'!F46) -> 13110.87 | G7: ='Income Statement Forecast'!G6*CHOOSE('DCF Valuation'!$I$33, 'Forecasted Assumptions'!G44, 'Forecasted Assumptions'!G45, 'Forecasted Assumptions'!G46) -> 13635.305 | H7: ='Income Statement Forecast'!H6*CHOOSE('DCF Valuation'!$I$33, 'Forecasted Assumptions'!H44, 'Forecasted Assumptions'!H45, 'Forecasted Assumptions'!H46) -> 14180.717 | I7: ='Income Statement Forecast'!I6*CHOOSE('DCF Valuation'!$I$33, 'Forecasted Assumptions'!I44, 'Forecasted Assumptions'!I45, 'Forecasted Assumptions'!I46) -> 14677.042 | J7: ='Income Statement Forecast'!J6*CHOOSE('DCF Valuation'!$I$33, 'Forecasted Assumptions'!J44, 'Forecasted Assumptions'!J45, 'Forecasted Assumptions'!J46) -> 15043.968
A8: Inventory | B8: {=INDEX('Balance Sheet'!$B$12:$E$12,6-COLUMN())} -> 1331 | C8: {=INDEX('Balance Sheet'!$B$12:$E$12,6-COLUMN())} -> 1742 | D8: {=INDEX('Balance Sheet'!$B$12:$E$12,6-COLUMN())} -> 1963 | E8: {=INDEX('Balance Sheet'!$B$12:$E$12,6-COLUMN())} -> 2022 | F8: ='Income Statement Forecast'!F6*CHOOSE('DCF Valuation'!$I$33, 'Forecasted Assumptions'!F49, 'Forecasted Assumptions'!F50, 'Forecasted Assumptions'!F51) -> 2082.66 | G8: ='Income Statement Forecast'!G6*CHOOSE('DCF Valuation'!$I$33, 'Forecasted Assumptions'!G49, 'Forecasted Assumptions'!G50, 'Forecasted Assumptions'!G51) -> 2165.9664 | H8: ='Income Statement Forecast'!H6*CHOOSE('DCF Valuation'!$I$33, 'Forecasted Assumptions'!H49, 'Forecasted Assumptions'!H50, 'Forecasted Assumptions'!H51) -> 2252.6051 | I8: ='Income Statement Forecast'!I6*CHOOSE('DCF Valuation'!$I$33, 'Forecasted Assumptions'!I49, 'Forecasted Assumptions'!I50, 'Forecasted Assumptions'!I51) -> 2331.4462 | J8: ='Income Statement Forecast'!J6*CHOOSE('DCF Valuation'!$I$33, 'Forecasted Assumptions'!J49, 'Forecasted Assumptions'!J50, 'Forecasted Assumptions'!J51) -> 2389.7324
A9: Prepaid Expenses | B9: 0 | C9: 0 | D9: 0 | E9: 0 | F9: =0 -> 0 | G9: =0 -> 0 | H9: =0 -> 0 | I9: =0 -> 0 | J9: =0 -> 0
A10: Other Current Assets | B10: {=INDEX('Balance Sheet'!$B$16:$E$16,6-COLUMN())} -> 3000 | C10: {=INDEX('Balance Sheet'!$B$16:$E$16,6-COLUMN())} -> 3089 | D10: {=INDEX('Balance Sheet'!$B$16:$E$16,6-COLUMN())} -> 4288 | E10: {=INDEX('Balance Sheet'!$B$16:$E$16,6-COLUMN())} -> 4488 | F10: ='Income Statement Forecast'!F6*'Forecasted Assumptions'!F74 -> 4622.64 | G10: ='Income Statement Forecast'!G6*'Forecasted Assumptions'!G74 -> 4807.5456 | H10: ='Income Statement Forecast'!H6*'Forecasted Assumptions'!H74 -> 4999.8474 | I10: ='Income Statement Forecast'!I6*'Forecasted Assumptions'!I74 -> 5174.8421 | J10: ='Income Statement Forecast'!J6*'Forecasted Assumptions'!J74 -> 5304.2131
A11: Total Current Assets | B11: =SUM(B6:B10) -> 33657 | C11: =SUM(C6:C10) -> 29098 | D11: =SUM(D6:D10) -> 32763 | E11: =SUM(E6:E10) -> 25241 | F11: =SUM(F6:F10) -> 25818.17 | G11: =SUM(G6:G10) -> 26610.817 | H11: =SUM(H6:H10) -> 27435.169 | I11: =SUM(I6:I10) -> 28185.33 | J11: =SUM(J6:J10) -> 28739.914
A13: Surplus Cash | F13: =IF((F29+F37+F45)>(F11+F20),(F29+F37+F45)-(F11+F20),0) -> 0 | G13: =IF((G29+G37+G45)>(G11+G20),(G29+G37+G45)-(G11+G20),0) -> 0 | H13: =IF((H29+H37+H45)>(H11+H20),(H29+H37+H45)-(H11+H20),0) -> 0 | I13: =IF((I29+I37+I45)>(I11+I20),(I29+I37+I45)-(I11+I20),0) -> 0 | J13: =IF((J29+J37+J45)>(J11+J20),(J29+J37+J45)-(J11+J20),0) -> 0
A15: Net Property, Plant & Equipment | B15: {=INDEX('Balance Sheet'!$B$25:$E$25,6-COLUMN())} -> 36855 | C15: {=INDEX('Balance Sheet'!$B$25:$E$25,6-COLUMN())} -> 37865 | D15: {=INDEX('Balance Sheet'!$B$25:$E$25,6-COLUMN())} -> 39443 | E15: {=INDEX('Balance Sheet'!$B$25:$E$25,6-COLUMN())} -> 40663 | F15: ='Income Statement Forecast'!F6*CHOOSE('DCF Valuation'!$I$33, 'Forecasted Assumptions'!F59, 'Forecasted Assumptions'!F60, 'Forecasted Assumptions'!F61) -> 41882.89 | G15: ='Income Statement Forecast'!G6*CHOOSE('DCF Valuation'!$I$33, 'Forecasted Assumptions'!G59, 'Forecasted Assumptions'!G60, 'Forecasted Assumptions'!G61) -> 43558.206 | H15: ='Income Statement Forecast'!H6*CHOOSE('DCF Valuation'!$I$33, 'Forecasted Assumptions'!H59, 'Forecasted Assumptions'!H60, 'Forecasted Assumptions'!H61) -> 45300.534 | I15: ='Income Statement Forecast'!I6*CHOOSE('DCF Valuation'!$I$33, 'Forecasted Assumptions'!I59, 'Forecasted Assumptions'!I60, 'Forecasted Assumptions'!I61) -> 46886.053 | J15: ='Income Statement Forecast'!J6*CHOOSE('DCF Valuation'!$I$33, 'Forecasted Assumptions'!J59, 'Forecasted Assumptions'!J60, 'Forecasted Assumptions'!J61) -> 48058.204
A16: Goodwill | B16: {=INDEX('Balance Sheet'!$B$27:$E$27,6-COLUMN())} -> 78071 | C16: {=INDEX('Balance Sheet'!$B$27:$E$27,6-COLUMN())} -> 77897 | D16: {=INDEX('Balance Sheet'!$B$27:$E$27,6-COLUMN())} -> 77067 | E16: {=INDEX('Balance Sheet'!$B$27:$E$27,6-COLUMN())} -> 73326 | F16: =E16 -> 73326 | G16: =F16 -> 73326 | H16: =G16 -> 73326 | I16: =H16 -> 73326 | J16: =I16 -> 73326
A17: Intangibles | B17: {=INDEX('Balance Sheet'!$B$28:$E$28,6-COLUMN())} -> 46664 | C17: {=INDEX('Balance Sheet'!$B$28:$E$28,6-COLUMN())} -> 50614 | D17: {=INDEX('Balance Sheet'!$B$28:$E$28,6-COLUMN())} -> 46652 | E17: {=INDEX('Balance Sheet'!$B$28:$E$28,6-COLUMN())} -> 43051 | F17: =E17 -> 43051 | G17: =F17 -> 43051 | H17: =G17 -> 43051 | I17: =H17 -> 43051 | J17: =I17 -> 43051
A18: Long-Term Investments | B18: {=INDEX('Balance Sheet'!$B$29:$E$29,6-COLUMN())} -> 3935 | C18: {=INDEX('Balance Sheet'!$B$29:$E$29,6-COLUMN())} -> 3218 | D18: {=INDEX('Balance Sheet'!$B$29:$E$29,6-COLUMN())} -> 3080 | E18: {=INDEX('Balance Sheet'!$B$29:$E$29,6-COLUMN())} -> 4459 | F18: =E18 -> 4459 | G18: =F18 -> 4459 | H18: =G18 -> 4459 | I18: =H18 -> 4459 | J18: =I18 -> 4459
A19: Other Long-Term Assets | B19: {=INDEX('Balance Sheet'!$B$32:$E$32,6-COLUMN())} -> 4427 | C19: {=INDEX('Balance Sheet'!$B$32:$E$32,6-COLUMN())} -> 4939 | D19: {=INDEX('Balance Sheet'!$B$32:$E$32,6-COLUMN())} -> 6574 | E19: {=INDEX('Balance Sheet'!$B$32:$E$32,6-COLUMN())} -> 9479 | F19: =E19 -> 9479 | G19: =F19 -> 9479 | H19: =G19 -> 9479 | I19: =H19 -> 9479 | J19: =I19 -> 9479
A20: Total Long Term Assets | B20: =SUM(B15:B19) -> 169952 | C20: =SUM(C15:C19) -> 174533 | D20: =SUM(D15:D19) -> 172816 | E20: =SUM(E15:E19) -> 170978 | F20: =SUM(F15:F19) -> 172197.89 | G20: =SUM(G15:G19) -> 173873.21 | H20: =SUM(H15:H19) -> 175615.53 | I20: =SUM(I15:I19) -> 177201.05 | J20: =SUM(J15:J19) -> 178373.2
A22: Total Assets | B22: =B11+B20 -> 203609 | C22: =C11+C20 -> 203631 | D22: =D11+D20 -> 205579 | E22: =E11+E20 -> 196219 | F22: =F11+F20+F13 -> 198016.06 | G22: =G11+G20+G13 -> 200484.02 | H22: =H11+H20+H13 -> 203050.7 | I22: =I11+I20+I13 -> 205386.38 | J22: =J11+J20+J13 -> 207113.12
A25: Accounts Payable | B25: {=INDEX('Balance Sheet'!$B$38:$E$38,6-COLUMN())} -> 16357 | C25: {=INDEX('Balance Sheet'!$B$38:$E$38,6-COLUMN())} -> 15554 | D25: {=INDEX('Balance Sheet'!$B$38:$E$38,6-COLUMN())} -> 14348 | E25: {=INDEX('Balance Sheet'!$B$38:$E$38,6-COLUMN())} -> 14022 | F25: ='Income Statement Forecast'!F6*CHOOSE('DCF Valuation'!$I$33, 'Forecasted Assumptions'!F64, 'Forecasted Assumptions'!F65, 'Forecasted Assumptions'!F66) -> 14442.66 | G25: ='Income Statement Forecast'!G6*CHOOSE('DCF Valuation'!$I$33, 'Forecasted Assumptions'!G64, 'Forecasted Assumptions'!G65, 'Forecasted Assumptions'!G66) -> 15020.366 | H25: ='Income Statement Forecast'!H6*CHOOSE('DCF Valuation'!$I$33, 'Forecasted Assumptions'!H64, 'Forecasted Assumptions'!H65, 'Forecasted Assumptions'!H66) -> 15621.181 | I25: ='Income Statement Forecast'!I6*CHOOSE('DCF Valuation'!$I$33, 'Forecasted Assumptions'!I64, 'Forecasted Assumptions'!I65, 'Forecasted Assumptions'!I66) -> 16167.922 | J25: ='Income Statement Forecast'!J6*CHOOSE('DCF Valuation'!$I$33, 'Forecasted Assumptions'!J64, 'Forecasted Assumptions'!J65, 'Forecasted Assumptions'!J66) -> 16572.12
A26: Accrued Expenses | B26: {=INDEX('Balance Sheet'!$B$39:$E$39,6-COLUMN())} -> 4119 | C26: {=INDEX('Balance Sheet'!$B$39:$E$39,6-COLUMN())} -> 4061 | D26: {=INDEX('Balance Sheet'!$B$39:$E$39,6-COLUMN())} -> 3801 | E26: {=INDEX('Balance Sheet'!$B$39:$E$39,6-COLUMN())} -> 4416 | F26: ='Income Statement Forecast'!F6*CHOOSE('DCF Valuation'!$I$33, 'Forecasted Assumptions'!F69, 'Forecasted Assumptions'!F70, 'Forecasted Assumptions'!F71) -> 4548.48 | G26: ='Income Statement Forecast'!G6*CHOOSE('DCF Valuation'!$I$33, 'Forecasted Assumptions'!G69, 'Forecasted Assumptions'!G70, 'Forecasted Assumptions'!G71) -> 4730.4192 | H26: ='Income Statement Forecast'!H6*CHOOSE('DCF Valuation'!$I$33, 'Forecasted Assumptions'!H69, 'Forecasted Assumptions'!H70, 'Forecasted Assumptions'!H71) -> 4919.636 | I26: ='Income Statement Forecast'!I6*CHOOSE('DCF Valuation'!$I$33, 'Forecasted Assumptions'!I69, 'Forecasted Assumptions'!I70, 'Forecasted Assumptions'!I71) -> 5091.8232 | J26: ='Income Statement Forecast'!J6*CHOOSE('DCF Valuation'!$I$33, 'Forecasted Assumptions'!J69, 'Forecasted Assumptions'!J70, 'Forecasted Assumptions'!J71) -> 5219.1188
A27: Current Portion of LT Debt/Capital Leases | B27: {=INDEX('Balance Sheet'!$B$41:$E$41,6-COLUMN())} -> 5907 | C27: {=INDEX('Balance Sheet'!$B$41:$E$41,6-COLUMN())} -> 3107 | D27: {=INDEX('Balance Sheet'!$B$41:$E$41,6-COLUMN())} -> 4367 | E27: {=INDEX('Balance Sheet'!$B$41:$E$41,6-COLUMN())} -> 6875 | F27: =E27 -> 6875 | G27: =F27 -> 6875 | H27: =G27 -> 6875 | I27: =H27 -> 6875 | J27: =I27 -> 6875
A28: Other Current Liabilities | B28: {=INDEX('Balance Sheet'!$B$42:$E$42,6-COLUMN())} -> 4694 | C28: {=INDEX('Balance Sheet'!$B$42:$E$42,6-COLUMN())} -> 6351 | D28: {=INDEX('Balance Sheet'!$B$42:$E$42,6-COLUMN())} -> 8623 | E28: {=INDEX('Balance Sheet'!$B$42:$E$42,6-COLUMN())} -> 9286 | F28: ='Income Statement Forecast'!F6*CHOOSE('DCF Valuation'!$I$33, 'Forecasted Assumptions'!F79, 'Forecasted Assumptions'!F80, 'Forecasted Assumptions'!F81) -> 9564.58 | G28: ='Income Statement Forecast'!G6*CHOOSE('DCF Valuation'!$I$33, 'Forecasted Assumptions'!G79, 'Forecasted Assumptions'!G80, 'Forecasted Assumptions'!G81) -> 9947.1632 | H28: ='Income Statement Forecast'!H6*CHOOSE('DCF Valuation'!$I$33, 'Forecasted Assumptions'!H79, 'Forecasted Assumptions'!H80, 'Forecasted Assumptions'!H81) -> 10345.05 | I28: ='Income Statement Forecast'!I6*CHOOSE('DCF Valuation'!$I$33, 'Forecasted Assumptions'!I79, 'Forecasted Assumptions'!I80, 'Forecasted Assumptions'!I81) -> 10707.126 | J28: ='Income Statement Forecast'!J6*CHOOSE('DCF Valuation'!$I$33, 'Forecasted Assumptions'!J79, 'Forecasted Assumptions'!J80, 'Forecasted Assumptions'!J81) -> 10974.805
A29: Total Current Liabilities | B29: =SUM(B25:B28) -> 31077 | C29: =SUM(C25:C28) -> 29073 | D29: =SUM(D25:D28) -> 31139 | E29: =SUM(E25:E28) -> 34599 | F29: =SUM(F25:F28) -> 35430.72 | G29: =SUM(G25:G28) -> 36572.949 | H29: =SUM(H25:H28) -> 37760.867 | I29: =SUM(I25:I28) -> 38841.872 | J29: =SUM(J25:J28) -> 39641.044
A31: Additional Financing Needed | F31: =IF((F11+F20)>(F29+F37+F45),(F11+F20)-(F29+F37+F45),0) -> 499.83 | G31: =IF((G11+G20)>(G29+G37+G45),(G11+G20)-(G29+G37+G45),0) -> 1186.2632 | H31: =IF((H11+H20)>(H29+H37+H45),(H11+H20)-(H29+H37+H45),0) -> 1900.1537 | I31: =IF((I11+I20)>(I29+I37+I45),(I11+I20)-(I29+I37+I45),0) -> 2549.7941 | J31: =IF((J11+J20)>(J29+J37+J45),(J11+J20)-(J29+J37+J45),0) -> 3030.064
A33: Long-Term Debt | B33: {=INDEX('Balance Sheet'!$B$46:$E$46,6-COLUMN())} -> 48786 | C33: {=INDEX('Balance Sheet'!$B$46:$E$46,6-COLUMN())} -> 45518 | D33: {=INDEX('Balance Sheet'!$B$46:$E$46,6-COLUMN())} -> 42307 | E33: {=INDEX('Balance Sheet'!$B$46:$E$46,6-COLUMN())} -> 39130 | F33: =E33 -> 39130 | G33: =F33 -> 39130 | H33: =G33 -> 39130 | I33: =H33 -> 39130 | J33: =I33 -> 39130
A34: Deferred Income Tax | B34: {=INDEX('Balance Sheet'!$B$50:$E$50,6-COLUMN())} -> 7246 | C34: {=INDEX('Balance Sheet'!$B$50:$E$50,6-COLUMN())} -> 8363 | D34: {=INDEX('Balance Sheet'!$B$50:$E$50,6-COLUMN())} -> 7258 | E34: {=INDEX('Balance Sheet'!$B$50:$E$50,6-COLUMN())} -> 6277 | F34: =E34 -> 6277 | G34: =F34 -> 6277 | H34: =G34 -> 6277 | I34: =H34 -> 6277 | J34: =I34 -> 6277
A35: Minority Interest | B35: {=INDEX('Balance Sheet'!$B$51:$E$51,6-COLUMN())} -> 13671 | C35: {=INDEX('Balance Sheet'!$B$51:$E$51,6-COLUMN())} -> 13370 | D35: {=INDEX('Balance Sheet'!$B$51:$E$51,6-COLUMN())} -> 13735 | E35: {=INDEX('Balance Sheet'!$B$51:$E$51,6-COLUMN())} -> 4826 | F35: ='Income Statement Forecast'!F6*CHOOSE('DCF Valuation'!$I$33, 'Forecasted Assumptions'!F84, 'Forecasted Assumptions'!F85, 'Forecasted Assumptions'!F86) -> 4970.78 | G35: ='Income Statement Forecast'!G6*CHOOSE('DCF Valuation'!$I$33, 'Forecasted Assumptions'!G84, 'Forecasted Assumptions'!G85, 'Forecasted Assumptions'!G86) -> 5169.6112 | H35: ='Income Statement Forecast'!H6*CHOOSE('DCF Valuation'!$I$33, 'Forecasted Assumptions'!H84, 'Forecasted Assumptions'!H85, 'Forecasted Assumptions'!H86) -> 5376.3956 | I35: ='Income Statement Forecast'!I6*CHOOSE('DCF Valuation'!$I$33, 'Forecasted Assumptions'!I84, 'Forecasted Assumptions'!I85, 'Forecasted Assumptions'!I86) -> 5564.5695 | J35: ='Income Statement Forecast'!J6*CHOOSE('DCF Valuation'!$I$33, 'Forecasted Assumptions'!J84, 'Forecasted Assumptions'!J85, 'Forecasted Assumptions'!J86) -> 5703.6837
A36: Other Total Liabilities | B36: {=INDEX('Balance Sheet'!$B$52:$E$52,6-COLUMN())} -> 14276 | C36: {=INDEX('Balance Sheet'!$B$52:$E$52,6-COLUMN())} -> 12299 | D36: {=INDEX('Balance Sheet'!$B$52:$E$52,6-COLUMN())} -> 11863 | E36: {=INDEX('Balance Sheet'!$B$52:$E$52,6-COLUMN())} -> 10691 | F36: ='Income Statement Forecast'!F6*CHOOSE('DCF Valuation'!$I$33, 'Forecasted Assumptions'!F89, 'Forecasted Assumptions'!F90, 'Forecasted Assumptions'!F91) -> 11011.73 | G36: ='Income Statement Forecast'!G6*CHOOSE('DCF Valuation'!$I$33, 'Forecasted Assumptions'!G89, 'Forecasted Assumptions'!G90, 'Forecasted Assumptions'!G91) -> 11452.199 | H36: ='Income Statement Forecast'!H6*CHOOSE('DCF Valuation'!$I$33, 'Forecasted Assumptions'!H89, 'Forecasted Assumptions'!H90, 'Forecasted Assumptions'!H91) -> 11910.287 | I36: ='Income Statement Forecast'!I6*CHOOSE('DCF Valuation'!$I$33, 'Forecasted Assumptions'!I89, 'Forecasted Assumptions'!I90, 'Forecasted Assumptions'!I91) -> 12327.147 | J36: ='Income Statement Forecast'!J6*CHOOSE('DCF Valuation'!$I$33, 'Forecasted Assumptions'!J89, 'Forecasted Assumptions'!J90, 'Forecasted Assumptions'!J91) -> 12635.326
A37: Total Long-Term Liabilities | B37: =SUM(B33:B36) -> 83979 | C37: =SUM(C33:C36) -> 79550 | D37: =SUM(D33:D36) -> 75163 | E37: =SUM(E33:E36) -> 60924 | F37: =SUM(F33:F36) -> 61389.51 | G37: =SUM(G33:G36) -> 62028.81 | H37: =SUM(H33:H36) -> 62693.683 | I37: =SUM(I33:I36) -> 63298.717 | J37: =SUM(J33:J36) -> 63746.01
A39: Total Liabilities | B39: =B29+B37 -> 115056 | C39: =C29+C37 -> 108623 | D39: =D29+D37 -> 106302 | E39: =E29+E37 -> 95523 | F39: =F29+F37 -> 96820.23 | G39: =G29+G37 -> 98601.759 | H39: =H29+H37 -> 100454.55 | I39: =I29+I37 -> 102140.59 | J39: =J29+J37 -> 103387.05
A41: Common Stock | B41: {=INDEX('Balance Sheet'!$B$58:$E$58,6-COLUMN())} -> 55471 | C41: {=INDEX('Balance Sheet'!$B$58:$E$58,6-COLUMN())} -> 56398 | D41: {=INDEX('Balance Sheet'!$B$58:$E$58,6-COLUMN())} -> 57383 | E41: {=INDEX('Balance Sheet'!$B$58:$E$58,6-COLUMN())} -> 58592 | F41: =E41 -> 58592 | G41: =F41 -> 58592 | H41: =G41 -> 58592 | I41: =H41 -> 58592 | J41: =I41 -> 58592
A42: Retained Earnings | B42: {=INDEX('Balance Sheet'!$B$61:$E$61,6-COLUMN())} -> 40429 | C42: {=INDEX('Balance Sheet'!$B$61:$E$61,6-COLUMN())} -> 43636 | D42: {=INDEX('Balance Sheet'!$B$61:$E$61,6-COLUMN())} -> 46093 | E42: {=INDEX('Balance Sheet'!$B$61:$E$61,6-COLUMN())} -> 49722 | F42: =E42 -> 49722 | G42: =F42 -> 49722 | H42: =G42 -> 49722 | I42: =H42 -> 49722 | J42: =I42 -> 49722
A43: Treasury Stock - Common | B43: {=INDEX('Balance Sheet'!$B$62:$E$62,6-COLUMN())} -> -907 | C43: {=INDEX('Balance Sheet'!$B$62:$E$62,6-COLUMN())} -> -907 | D43: {=INDEX('Balance Sheet'!$B$62:$E$62,6-COLUMN())} -> -907 | E43: {=INDEX('Balance Sheet'!$B$62:$E$62,6-COLUMN())} -> -3919 | F43: =E43 -> -3919 | G43: =F43 -> -3919 | H43: =G43 -> -3919 | I43: =H43 -> -3919 | J43: =I43 -> -3919
A44: Other Total Equity | B44: {=INDEX('Balance Sheet'!$B$65:$E$65,6-COLUMN())} -> -6440 | C44: {=INDEX('Balance Sheet'!$B$65:$E$65,6-COLUMN())} -> -4119 | D44: {=INDEX('Balance Sheet'!$B$65:$E$65,6-COLUMN())} -> -3292 | E44: {=INDEX('Balance Sheet'!$B$65:$E$65,6-COLUMN())} -> -3699 | F44: =E44 -> -3699 | G44: =F44 -> -3699 | H44: =G44 -> -3699 | I44: =H44 -> -3699 | J44: =I44 -> -3699
A45: Total Shareholders' Equity | B45: =SUM(B41:B44) -> 88553 | C45: =SUM(C41:C44) -> 95008 | D45: =SUM(D41:D44) -> 99277 | E45: =SUM(E41:E44) -> 100696 | F45: =SUM(F41:F44) -> 100696 | G45: =SUM(G41:G44) -> 100696 | H45: =SUM(H41:H44) -> 100696 | I45: =SUM(I41:I44) -> 100696 | J45: =SUM(J41:J44) -> 100696
A47: Total Liabilities & Shareholders' Equity | B47: =B39+B45 -> 203609 | C47: =C39+C45 -> 203631 | D47: =D39+D45 -> 205579 | E47: =E39+E45 -> 196219 | F47: =F39+F45+F31 -> 198016.06 | G47: =G39+G45+G31 -> 200484.02 | H47: =H39+H45+H31 -> 203050.7 | I47: =I39+I45+I31 -> 205386.38 | J47: =J39+J45+J31 -> 207113.12
A49: Check | B49: =IF(B22-B47 = 0, "BALANCED", B22-B47) -> BALANCED | C49: =IF(C22-C47 = 0, "BALANCED", C22-C47) -> BALANCED | D49: =IF(D22-D47 = 0, "BALANCED", D22-D47) -> BALANCED | E49: =IF(E22-E47 = 0, "BALANCED", E22-E47) -> BALANCED | F49: =IF(F22-F47 = 0, "BALANCED", F22-F47) -> BALANCED | G49: =IF(G22-G47 = 0, "BALANCED", G22-G47) -> BALANCED | H49: =IF(H22-H47 = 0, "BALANCED", H22-H47) -> BALANCED | I49: =IF(I22-I47 = 0, "BALANCED", I22-I47) -> BALANCED | J49: =IF(J22-J47 = 0, "BALANCED", J22-J47) -> BALANCED

Sheet Cash Flows Forecast
A1: 3 Statement Model - Cash Flow | C1: 2021A | D1: 2022A | E1: 2023A | F1: 2024A | G1: 2025E | H1: 2026E | I1: 2027E | J1: 2028E | K1: 2029E
A3: CASH FLOW STATEMENT
A4: ($ in millions)
A6: Net Income | C6: ='Income Statement Forecast'!B23 -> 2536 | D6: ='Income Statement Forecast'!C23 -> 3553 | E6: ='Income Statement Forecast'!D23 -> 3390 | F6: ='Income Statement Forecast'!E23 -> 5773 | G6: ='Income Statement Forecast'!F23 -> 8572.6054 | H6: ='Income Statement Forecast'!G23 -> 10410.398 | I6: ='Income Statement Forecast'!H23 -> 11798.551 | J6: ='Income Statement Forecast'!I23 -> 12213.287 | K6: ='Income Statement Forecast'!J23 -> 14166.968
A7: Depreciation and Amortization | C7: =-'Income Statement Forecast'!B13 -> 5111 | D7: =-'Income Statement Forecast'!C13 -> 5163 | E7: =-'Income Statement Forecast'!D13 -> 5369 | F7: =-'Income Statement Forecast'!E13 -> 4990 | G7: =-'Income Statement Forecast'!F13 -> 5139.7 | H7: =-'Income Statement Forecast'!G13 -> 5345.288 | I7: =-'Income Statement Forecast'!H13 -> 5559.0995 | J7: =-'Income Statement Forecast'!I13 -> 5753.668 | K7: =-'Income Statement Forecast'!J13 -> 5897.5097
A8: Change in NCWC | C8: {=INDEX('Cash Flow Statement'!$B$11:$E$11,7-COLUMN())} -> 2194 | D8: {=INDEX('Cash Flow Statement'!$B$11:$E$11,7-COLUMN())} -> 488 | E8: {=INDEX('Cash Flow Statement'!$B$11:$E$11,7-COLUMN())} -> 177 | F8: {=INDEX('Cash Flow Statement'!$B$11:$E$11,7-COLUMN())} -> -1613 | G8: =('Balance Sheet Forecast'!F11-'Balance Sheet Forecast'!E11)-('Balance Sheet Forecast'!F29-'Balance Sheet Forecast'!E29) -> -254.55 | H8: =('Balance Sheet Forecast'!G11-'Balance Sheet Forecast'!F11)-('Balance Sheet Forecast'!G29-'Balance Sheet Forecast'!F29) -> -349.582 | I8: =('Balance Sheet Forecast'!H11-'Balance Sheet Forecast'!G11)-('Balance Sheet Forecast'!H29-'Balance Sheet Forecast'!G29) -> -363.56528 | J8: =('Balance Sheet Forecast'!I11-'Balance Sheet Forecast'!H11)-('Balance Sheet Forecast'!I29-'Balance Sheet Forecast'!H29) -> -330.8444 | K8: =('Balance Sheet Forecast'!J11-'Balance Sheet Forecast'!I11)-('Balance Sheet Forecast'!J29-'Balance Sheet Forecast'!I29) -> -244.58854
A9: Cash Flow from Operating Activities | C9: =SUM(C6:C8) -> 9841 | D9: =SUM(D6:D8) -> 9204 | E9: =SUM(E6:E8) -> 8936 | F9: =SUM(F6:F8) -> 9150 | G9: =SUM(G6:G8) -> 13457.755 | H9: =SUM(H6:H8) -> 15406.104 | I9: =SUM(I6:I8) -> 16994.085 | J9: =SUM(J6:J8) -> 17636.111 | K9: =SUM(K6:K8) -> 19819.889
A11: Capital Expenditures | C11: {=INDEX('Cash Flow Statement'!$B$19:$E$19,7-COLUMN())} -> -3578 | D11: {=INDEX('Cash Flow Statement'!$B$19:$E$19,7-COLUMN())} -> -4943 | E11: {=INDEX('Cash Flow Statement'!$B$19:$E$19,7-COLUMN())} -> -4969 | F11: {=INDEX('Cash Flow Statement'!$B$19:$E$19,7-COLUMN())} -> -5412 | G11: =-'Income Statement Forecast'!F6*CHOOSE('DCF Valuation'!$I$33, 'Forecasted Assumptions'!F96, 'Forecasted Assumptions'!F97, 'Forecasted Assumptions'!F98) -> -5574.36 | H11: =-'Income Statement Forecast'!G6*'Forecasted Assumptions'!G96 -> -5797.3344 | I11: =-'Income Statement Forecast'!H6*'Forecasted Assumptions'!H96 -> -6029.2278 | J11: =-'Income Statement Forecast'!I6*'Forecasted Assumptions'!I96 -> -6240.2507 | K11: =-'Income Statement Forecast'!J6*'Forecasted Assumptions'!J96 -> -6396.257
A12: Other Total Investing Cash Flow Items | C12: {=INDEX('Cash Flow Statement'!$B$21:$E$21,7-COLUMN())} -> 415 | D12: {=INDEX('Cash Flow Statement'!$B$21:$E$21,7-COLUMN())} -> -65 | E12: {=INDEX('Cash Flow Statement'!$B$21:$E$21,7-COLUMN())} -> 328 | F12: {=INDEX('Cash Flow Statement'!$B$21:$E$21,7-COLUMN())} -> -1469 | G12: =F12 -> -1469 | H12: =G12 -> -1469 | I12: =H12 -> -1469 | J12: =I12 -> -1469 | K12: =J12 -> -1469
A13: Cash Flow from Investing Activities | C13: =SUM(C11:C12) -> -3163 | D13: =SUM(D11:D12) -> -5008 | E13: =SUM(E11:E12) -> -4641 | F13: =SUM(F11:F12) -> -6881 | G13: =SUM(G11:G12) -> -7043.36 | H13: =SUM(H11:H12) -> -7266.3344 | I13: =SUM(I11:I12) -> -7498.2278 | J13: =SUM(J11:J12) -> -7709.2507 | K13: =SUM(K11:K12) -> -7865.257
A15: Total Cash Dividends Paid | C15: {=INDEX('Cash Flow Statement'!$B$30:$E$30,7-COLUMN())} -> 0 | D15: {=INDEX('Cash Flow Statement'!$B$30:$E$30,7-COLUMN())} -> 0 | E15: {=INDEX('Cash Flow Statement'!$B$30:$E$30,7-COLUMN())} -> -- | F15: {=INDEX('Cash Flow Statement'!$B$30:$E$30,7-COLUMN())} -> -1366 | G15: =-'Income Statement Forecast'!F6*CHOOSE('DCF Valuation'!$I$33, 'Forecasted Assumptions'!F101, 'Forecasted Assumptions'!F102, 'Forecasted Assumptions'!F103) -> -1406.98 | H15: =-'Income Statement Forecast'!G6*CHOOSE('DCF Valuation'!$I$33, 'Forecasted Assumptions'!G101, 'Forecasted Assumptions'!G102, 'Forecasted Assumptions'!G103) -> -1463.2592 | I15: =-'Income Statement Forecast'!H6*CHOOSE('DCF Valuation'!$I$33, 'Forecasted Assumptions'!H101, 'Forecasted Assumptions'!H102, 'Forecasted Assumptions'!H103) -> -1521.7896 | J15: =-'Income Statement Forecast'!I6*CHOOSE('DCF Valuation'!$I$33, 'Forecasted Assumptions'!I101, 'Forecasted Assumptions'!I102, 'Forecasted Assumptions'!I103) -> -1575.0522 | K15: =-'Income Statement Forecast'!J6*CHOOSE('DCF Valuation'!$I$33, 'Forecasted Assumptions'!J101, 'Forecasted Assumptions'!J102, 'Forecasted Assumptions'!J103) -> -1614.4285
A16: Issuance (Retirement) of Stock, Net | C16: {=INDEX('Cash Flow Statement'!$B$32:$E$32,7-COLUMN())} -> 435 | D16: {=INDEX('Cash Flow Statement'!$B$32:$E$32,7-COLUMN())} -> 127 | E16: {=INDEX('Cash Flow Statement'!$B$32:$E$32,7-COLUMN())} -> 52 | F16: {=INDEX('Cash Flow Statement'!$B$32:$E$32,7-COLUMN())} -> -2992 | G16: =F16 -> -2992 | H16: =G16 -> -2992 | I16: =H16 -> -2992 | J16: =I16 -> -2992 | K16: =J16 -> -2992
A17: Issuance (Retirement) of Debt, Net | C17: {=INDEX('Cash Flow Statement'!$B$36:$E$36,7-COLUMN())} -> -3699 | D17: {=INDEX('Cash Flow Statement'!$B$36:$E$36,7-COLUMN())} -> -4017 | E17: {=INDEX('Cash Flow Statement'!$B$36:$E$36,7-COLUMN())} -> -1783 | F17: {=INDEX('Cash Flow Statement'!$B$36:$E$36,7-COLUMN())} -> -1400 | G17: =F17 -> -1400 | H17: =G17 -> -1400 | I17: =H17 -> -1400 | J17: =I17 -> -1400 | K17: =J17 -> -1400
A18: Cash Flow from Financing Activities | C18: =SUM(C15:C17) -> -3264 | D18: =SUM(D15:D17) -> -3890 | E18: =SUM(E15:E17) -> -1731 | F18: =SUM(F15:F17) -> -5758 | G18: =SUM(G15:G17) -> -5798.98 | H18: =SUM(H15:H17) -> -5855.2592 | I18: =SUM(I15:I17) -> -5913.7896 | J18: =SUM(J15:J17) -> -5967.0522 | K18: =SUM(K15:K17) -> -6006.4285
A19: Foreign Exchange Effects | C19: {=INDEX('Cash Flow Statement'!$B$43:$E$43,7-COLUMN())} -> 30 | D19: {=INDEX('Cash Flow Statement'!$B$43:$E$43,7-COLUMN())} -> -603 | E19: {=INDEX('Cash Flow Statement'!$B$43:$E$43,7-COLUMN())} -> 73 | F19: {=INDEX('Cash Flow Statement'!$B$43:$E$43,7-COLUMN())} -> 65 | G19: =F19 -> 65 | H19: =G19 -> 65 | I19: =H19 -> 65 | J19: =I19 -> 65 | K19: =J19 -> 65
A20: Net Change in Cash | C20: =C9+C13+C18+C19 -> 3444 | D20: =D9+D13+D18+D19 -> -297 | E20: =E9+E13+E18+E19 -> 2637 | F20: =F9+F13+F18+F19 -> -3424 | G20: =G9+G13+G18 -> 615.41541 | H20: =H9+H13+H18 -> 2284.5109 | I20: =I9+I13+I18 -> 3582.0675 | J20: =J9+J13+J18 -> 3959.8076 | K20: =K9+K13+K18 -> 5948.2037

Sheet Ratio Analysis
B2: Ratio Analysis | C2: 2021A | D2: 2022A | E2: 2023A | F2: 2024A | G2: 2025E | H2: 2026E | I2: 2027E | J2: 2028E | K2: 2029E
B4: Liquidity
B5: Current ratio | C5: ='Balance Sheet Forecast'!B11/'Balance Sheet Forecast'!B29 -> 1.0830196 | D5: ='Balance Sheet Forecast'!C11/'Balance Sheet Forecast'!C29 -> 1.0008599 | E5: ='Balance Sheet Forecast'!D11/'Balance Sheet Forecast'!D29 -> 1.0521532 | F5: ='Balance Sheet Forecast'!E11/'Balance Sheet Forecast'!E29 -> 0.72952976 | G5: ='Balance Sheet Forecast'!F11/'Balance Sheet Forecast'!F29 -> 0.72869448 | H5: ='Balance Sheet Forecast'!G11/'Balance Sheet Forecast'!G29 -> 0.72760928 | I5: ='Balance Sheet Forecast'!H11/'Balance Sheet Forecast'!H29 -> 0.72655031 | J5: ='Balance Sheet Forecast'!I11/'Balance Sheet Forecast'!I29 -> 0.72564294 | K5: ='Balance Sheet Forecast'!J11/'Balance Sheet Forecast'!J29 -> 0.72500396
B7: Activity
B8: Receivables turnover | C8: ='Income Statement Forecast'!B6/'Balance Sheet Forecast'!B7 -> 5.0436149 | D8: ='Income Statement Forecast'!C6/'Balance Sheet Forecast'!C7 -> 6.5382548 | E8: ='Income Statement Forecast'!D6/'Balance Sheet Forecast'!D7 -> 7.2098946 | F8: ='Income Statement Forecast'!E6/'Balance Sheet Forecast'!E7 -> 7.1773902 | G8: ='Income Statement Forecast'!F6/'Balance Sheet Forecast'!F7 -> 7.1773902 | H8: ='Income Statement Forecast'!G6/'Balance Sheet Forecast'!G7 -> 7.1773902 | I8: ='Income Statement Forecast'!H6/'Balance Sheet Forecast'!H7 -> 7.1773902 | J8: ='Income Statement Forecast'!I6/'Balance Sheet Forecast'!I7 -> 7.1773902 | K8: ='Income Statement Forecast'!J6/'Balance Sheet Forecast'!J7 -> 7.1773902
B9: Average Receivables Collection Period | C9: =365/C8 -> 72.368729 | D9: =365/D8 -> 55.825294 | E9: =365/E8 -> 50.624873 | F9: =365/F8 -> 50.854139 | G9: =365/G8 -> 50.854139 | H9: =365/H8 -> 50.854139 | I9: =365/I8 -> 50.854139 | J9: =365/J8 -> 50.854139 | K9: =365/K8 -> 50.854139
B10: Fixed asset turnover | C10: ='Income Statement Forecast'!B6/'Balance Sheet Forecast'!B15 -> 1.8292769 | D10: ='Income Statement Forecast'!C6/'Balance Sheet Forecast'!C15 -> 2.184656 | E10: ='Income Statement Forecast'!D6/'Balance Sheet Forecast'!D15 -> 2.2538346 | F10: ='Income Statement Forecast'!E6/'Balance Sheet Forecast'!E15 -> 2.2467845 | G10: ='Income Statement Forecast'!F6/'Balance Sheet Forecast'!F15 -> 2.2467845 | H10: ='Income Statement Forecast'!G6/'Balance Sheet Forecast'!G15 -> 2.2467845 | I10: ='Income Statement Forecast'!H6/'Balance Sheet Forecast'!H15 -> 2.2467845 | J10: ='Income Statement Forecast'!I6/'Balance Sheet Forecast'!I15 -> 2.2467845 | K10: ='Income Statement Forecast'!J6/'Balance Sheet Forecast'!J15 -> 2.2467845
B11: Total asset turnover | C11: ='Income Statement Forecast'!B6/'Balance Sheet Forecast'!B22 -> 0.33111503 | D11: ='Income Statement Forecast'!C6/'Balance Sheet Forecast'!C22 -> 0.40623481 | E11: ='Income Statement Forecast'!D6/'Balance Sheet Forecast'!D22 -> 0.43242744 | F11: ='Income Statement Forecast'!E6/'Balance Sheet Forecast'!E22 -> 0.46560731 | G11: ='Income Statement Forecast'!F6/'Balance Sheet Forecast'!F22 -> 0.47522322 | H11: ='Income Statement Forecast'!G6/'Balance Sheet Forecast'!G22 -> 0.48814814 | I11: ='Income Statement Forecast'!H6/'Balance Sheet Forecast'!H22 -> 0.50125677 | J11: ='Income Statement Forecast'!I6/'Balance Sheet Forecast'!I22 -> 0.51290089 | K11: ='Income Statement Forecast'!J6/'Balance Sheet Forecast'!J22 -> 0.52134037
B13: Debt Management
B14: Debt Ratio | C14: ='Balance Sheet Forecast'!B37/'Balance Sheet Forecast'!B22 -> 0.4124523 | D14: ='Balance Sheet Forecast'!C37/'Balance Sheet Forecast'!C22 -> 0.39065761 | E14: ='Balance Sheet Forecast'!D37/'Balance Sheet Forecast'!D22 -> 0.36561614 | F14: ='Balance Sheet Forecast'!E37/'Balance Sheet Forecast'!E22 -> 0.31048981 | G14: ='Balance Sheet Forecast'!F37/'Balance Sheet Forecast'!F22 -> 0.31002288 | H14: ='Balance Sheet Forecast'!G37/'Balance Sheet Forecast'!G22 -> 0.30939528 | I14: ='Balance Sheet Forecast'!H37/'Balance Sheet Forecast'!H22 -> 0.30875876 | J14: ='Balance Sheet Forecast'!I37/'Balance Sheet Forecast'!I22 -> 0.30819335 | K14: ='Balance Sheet Forecast'!J37/'Balance Sheet Forecast'!J22 -> 0.30778355
B16: Profitability
B17: Gross margin | C17: ='Income Statement Forecast'!B8/'Income Statement Forecast'!B6 -> 0.33057937 | D17: ='Income Statement Forecast'!C8/'Income Statement Forecast'!C6 -> 0.34236358 | E17: ='Income Statement Forecast'!D8/'Income Statement Forecast'!D6 -> 0.33405701 | F17: ='Income Statement Forecast'!E8/'Income Statement Forecast'!E6 -> 0.35751579 | G17: ='Income Statement Forecast'!F8/'Income Statement Forecast'!F6 -> 0.35 | H17: ='Income Statement Forecast'!G8/'Income Statement Forecast'!G6 -> 0.37 | I17: ='Income Statement Forecast'!H8/'Income Statement Forecast'!H6 -> 0.38 | J17: ='Income Statement Forecast'!I8/'Income Statement Forecast'!I6 -> 0.38 | K17: ='Income Statement Forecast'!J8/'Income Statement Forecast'!J6 -> 0.4
B18: Operating margin | C18: ='Income Statement Forecast'!B16/'Income Statement Forecast'!B6 -> 0.046441603 | D18: ='Income Statement Forecast'!C16/'Income Statement Forecast'!C6 -> 0.078927009 | E18: ='Income Statement Forecast'!D16/'Income Statement Forecast'!D6 -> 0.056547954 | F18: ='Income Statement Forecast'!E16/'Income Statement Forecast'!E6 -> 0.090344896 | G18: ='Income Statement Forecast'!F16/'Income Statement Forecast'!F6 -> 0.12288996 | H18: ='Income Statement Forecast'!G16/'Income Statement Forecast'!G6 -> 0.14288996 | I18: ='Income Statement Forecast'!H16/'Income Statement Forecast'!H6 -> 0.15538151 | J18: ='Income Statement Forecast'!I16/'Income Statement Forecast'!I6 -> 0.15538151 | K18: ='Income Statement Forecast'!J16/'Income Statement Forecast'!J6 -> 0.17538151
B19: Profit margin on sales | C19: ='Income Statement Forecast'!B23/'Income Statement Forecast'!B6 -> 0.037616067 | D19: ='Income Statement Forecast'!C23/'Income Statement Forecast'!C6 -> 0.042951089 | E19: ='Income Statement Forecast'!D23/'Income Statement Forecast'!D6 -> 0.038133591 | F19: ='Income Statement Forecast'!E23/'Income Statement Forecast'!E6 -> 0.063188888 | G19: ='Income Statement Forecast'!F23/'Income Statement Forecast'!F6 -> 0.091099242 | H19: ='Income Statement Forecast'!G23/'Income Statement Forecast'!G6 -> 0.10637411 | I19: ='Income Statement Forecast'!H23/'Income Statement Forecast'!H6 -> 0.11592148 | J19: ='Income Statement Forecast'!I23/'Income Statement Forecast'!I6 -> 0.11593844 | K19: ='Income Statement Forecast'!J23/'Income Statement Forecast'!J6 -> 0.13120426
B20: Return on assets | C20: ='Income Statement Forecast'!B23/'Balance Sheet Forecast'!B22 -> 0.012455245 | D20: ='Income Statement Forecast'!C23/'Balance Sheet Forecast'!C22 -> 0.017448227 | E20: ='Income Statement Forecast'!D23/'Balance Sheet Forecast'!D22 -> 0.016490011 | F20: ='Income Statement Forecast'!E23/'Balance Sheet Forecast'!E22 -> 0.029421208 | G20: ='Income Statement Forecast'!F23/'Balance Sheet Forecast'!F22 -> 0.043292475 | H20: ='Income Statement Forecast'!G23/'Balance Sheet Forecast'!G22 -> 0.051926325 | I20: ='Income Statement Forecast'!H23/'Balance Sheet Forecast'!H22 -> 0.058106426 | J20: ='Income Statement Forecast'!I23/'Balance Sheet Forecast'!I22 -> 0.05946493 | K20: ='Income Statement Forecast'!J23/'Balance Sheet Forecast'!J22 -> 0.06840208
B21: Return on equity | C21: ='Income Statement Forecast'!B23/'Balance Sheet Forecast'!B45 -> 0.028638217 | D21: ='Income Statement Forecast'!C23/'Balance Sheet Forecast'!C45 -> 0.037396851 | E21: ='Income Statement Forecast'!D23/'Balance Sheet Forecast'!D45 -> 0.034146882 | F21: ='Income Statement Forecast'!E23/'Balance Sheet Forecast'!E45 -> 0.057330976 | G21: ='Income Statement Forecast'!F23/'Balance Sheet Forecast'!F45 -> 0.085133525 | H21: ='Income Statement Forecast'!G23/'Balance Sheet Forecast'!G45 -> 0.10338443 | I21: ='Income Statement Forecast'!H23/'Balance Sheet Forecast'!H45 -> 0.11717 | J21: ='Income Statement Forecast'!I23/'Balance Sheet Forecast'!I45 -> 0.1212887 | K21: ='Income Statement Forecast'!J23/'Balance Sheet Forecast'!J45 -> 0.14069047
B23: Dupont Analysis
B24: Profit Margin on Sales | C24: =C19 -> 0.037616067 | D24: =D19 -> 0.042951089 | E24: =E19 -> 0.038133591 | F24: =F19 -> 0.063188888 | G24: =G19 -> 0.091099242 | H24: =H19 -> 0.10637411 | I24: =I19 -> 0.11592148 | J24: =J19 -> 0.11593844 | K24: =K19 -> 0.13120426
B25: Total Asset Turnover | C25: =C11 -> 0.33111503 | D25: =D11 -> 0.40623481 | E25: =E11 -> 0.43242744 | F25: =F11 -> 0.46560731 | G25: =G11 -> 0.47522322 | H25: =H11 -> 0.48814814 | I25: =I11 -> 0.50125677 | J25: =J11 -> 0.51290089 | K25: =K11 -> 0.52134037
B26: Equity Multiplier | C26: ='Balance Sheet Forecast'!B22/'Balance Sheet Forecast'!B45 -> 2.2992897 | D26: ='Balance Sheet Forecast'!C22/'Balance Sheet Forecast'!C45 -> 2.1433037 | E26: ='Balance Sheet Forecast'!D22/'Balance Sheet Forecast'!D45 -> 2.0707616 | F26: ='Balance Sheet Forecast'!E22/'Balance Sheet Forecast'!E45 -> 1.9486276 | G26: ='Balance Sheet Forecast'!F22/'Balance Sheet Forecast'!F45 -> 1.9664739 | H26: ='Balance Sheet Forecast'!G22/'Balance Sheet Forecast'!G45 -> 1.990983 | I26: ='Balance Sheet Forecast'!H22/'Balance Sheet Forecast'!H45 -> 2.0164724 | J26: ='Balance Sheet Forecast'!I22/'Balance Sheet Forecast'!I45 -> 2.0396677 | K26: ='Balance Sheet Forecast'!J22/'Balance Sheet Forecast'!J45 -> 2.0568157
B27: ROE | C27: =C24*C25*C26 -> 0.028638217 | D27: =D24*D25*D26 -> 0.037396851 | E27: =E24*E25*E26 -> 0.034146882 | F27: =F24*F25*F26 -> 0.057330976 | G27: =G24*G25*G26 -> 0.085133525 | H27: =H24*H25*H26 -> 0.10338443 | I27: =I24*I25*I26 -> 0.11717 | J27: =J24*J25*J26 -> 0.1212887 | K27: =K24*K25*K26 -> 0.14069047

Sheet Financials -->

Sheet Income Statement
B1: 2024 | C1: 2023 | D1: 2022 | E1: 2021
A2: Revenue | B2: 91361 | C2: 88898 | D2: 82722 | E2: 67418
A3: Net Sales | B3: 91361 | C3: 88898 | D3: 82722 | E3: 67418
A4: Other Revenue, Total | B4: -- | C4: -- | D4: -- | E4: --
A5: Total Revenue | B5: 91361 | C5: 88898 | D5: 82722 | E5: 67418
A6: Cost of Revenue, Total | B6: 58698 | C6: 59201 | D6: 54401 | E6: 45131
A7: Cost of Revenue | B7: 58698 | C7: 59201 | D7: 54401 | E7: 45131
A8: Gross Profit | B8: 32663 | C8: 29697 | D8: 28321 | E8: 22287
A9: Selling/General/Admin. Expenses, Total | B9: 15759 | C9: 15336 | D9: 16388 | E9: 13517
A10: Selling/General/Administrative Expense | B10: 15759 | C10: 15336 | D10: 16388 | E10: 13517
A11: Research & Development | B11: -- | C11: -- | D11: -- | E11: --
A12: Depreciation/Amortization | B12: 4990 | C12: 5369 | D12: 5163 | E12: 5111
A13: Interest Expense, Net - Operating | B13: -- | C13: -- | D13: -- | E13: --
A14: Interest/Investment Income - Operating | B14: -- | C14: -- | D14: -- | E14: --
A15: Interest Expense(Income) - Net Operating | B15: -- | C15: -- | D15: -- | E15: --
A16: Interest Exp.(Inc.),Net-Operating, Total | B16: -- | C16: -- | D16: -- | E16: --
A17: Unusual Expense (Income) | B17: 3660 | C17: 3892 | D17: 237 | E17: 528
A18: Other Operating Expenses, Total | B18: -- | C18: 73 | D18: 4 | E18: --
A19: Total Operating Expense | B19: 83107 | C19: 83871 | D19: 76193 | E19: 64287
A20: Operating Income | B20: 8254 | C20: 5027 | D20: 6529 | E20: 3131
A21: Interest Expense, Net Non-Operating | B21: -2070 | C21: -1973 | D21: -1549 | E21: -1546
A22: Interest Expense - Non-Operating | B22: -2070 | C22: -1973 | D22: -1549 | E22: -1546
A23: Interest/Invest Income - Non-Operating | B23: 981 | C23: 1375 | D23: 243 | E23: 976
A24: Interest Income - Non-Operating | B24: 406 | C24: 424 | D24: 90 | E24: 140
A25: Interest Income(Exp), Net Non-Operating | B25: -- | C25: -- | D25: -- | E25: --
A26: Interest Inc.(Exp.),Net-Non-Op., Total | B26: -1089 | C26: -598 | D26: -1306 | E26: -570
A27: Gain (Loss) on Sale of Assets | B27: -- | C27: -- | D27: -- | E27: --
A28: Other, Net | B28: 404 | C28: 340 | D28: 62 | E28: --
A29: Other Non-Operating Income (Expense) | B29: 404 | C29: 340 | D29: 62 | E29: --
A30: Net Income Before Taxes | B30: 7569 | C30: 4769 | D30: 5285 | E30: 2561
A31: Provision for Income Taxes | B31: 1796 | C31: 1379 | D31: 1732 | E31: 25
A32: Net Income After Taxes | B32: 5773 | C32: 3390 | D32: 3553 | E32: 2536
A33: Minority Interest | B33: -801 | C33: -1036 | D33: -360 | E33: -512
A34: Equity In Affiliates | B34: -- | C34: -- | D34: -- | E34: --
A35: U.S. GAAP Adjustment | B35: -- | C35: -- | D35: -- | E35: --
A36: Net Income Before Extra. Items | B36: 4972 | C36: 2354 | D36: 3193 | E36: 2024
A37: Accounting Change | B37: -- | C37: -- | D37: -- | E37: --
A38: Discontinued Operations | B38: 0 | C38: 0 | D38: -62 | E38: -38
A39: Extraordinary Item | B39: -- | C39: -- | D39: -- | E39: --
A40: Tax on Extraordinary Items | B40: -- | C40: -- | D40: 14 | E40: 9
...

Sheet Balance Sheet
A1: Balance SheetQUARTERLYANNUAL
B2: 45563 | C2: 45199 | D2: 44835 | E2: 44471
A3: ASSETS
A4: Cash and Short Term Investments | B4: 6002 | C4: 14182 | D4: 11615 | E4: 15959
A5: Cash | B5: -- | C5: -- | D5: -- | E5: --
A6: Cash & Equivalents | B6: 6002 | C6: 14182 | D6: 11615 | E6: 15959
A7: Short Term Investments | B7: -- | C7: -- | D7: -- | E7: --
A8: Accounts Receivable - Trade, Net | B8: 10258 | C8: 10064 | D8: 10653 | E8: 11007
A9: Accounts Receivable - Trade, Gross | B9: 10341 | C9: 10179 | D9: 10811 | E9: 11177
A10: Total Receivables, Net | B10: 12729 | C10: 12330 | D10: 12652 | E10: 13367
A11: Receivables - Other | B11: 2471 | C11: 2266 | D11: 1999 | E11: 2360
A12: Total Inventory | B12: 2022 | C12: 1963 | D12: 1742 | E12: 1331
A13: Inventories - Finished Goods | B13: -- | C13: -- | D13: -- | E13: --
A14: Inventories - Work In Progress | B14: -- | C14: -- | D14: -- | E14: --
A15: Prepaid Expenses | B15: -- | C15: -- | D15: -- | E15: --
A16: Other Current Assets, Total | B16: 4488 | C16: 4288 | D16: 3089 | E16: 3000
A17: Restricted Cash - Current | B17: 0 | C17: 0 | D17: 3 | E17: 3
A18: Other Current Assets | B18: 4488 | C18: 4288 | D18: 3086 | E18: 2997
A19: Total Current Assets | B19: 25241 | C19: 32763 | D19: 29098 | E19: 33657
